Workbook

Sheet Sheet1
A1: Department | B1: Programme | C1: Shift | D1: Staff Incharge | E1: Course Title | F1: Course Code
A2: ARTIFICIAL INTELLIGENCE | B2: PG | C2: Shift 2 | D2: C.MOHANRAJA | E2: Research Writing | F2: 25PAI2SL02
A3: ARTIFICIAL INTELLIGENCE | B3: UG | C3: Shift 2 | D3: Dr. S. LAKSHMANAN | E3: Python for Data Science | F3: 25UAI24SL01
A4: B. COM BUSINESS ANALYTICS | B4: UG | C4: Shift 2 | D4: Santhosh | E4: Applied Digital Entrepreneurship | F4: 25UCB24SL01
A5: B. COM HONOURS | B5: UG | C5: Shift 2 | D5: G Prabhakaran | E5: Digital Marketing in the AI Era-Part 1 | F5: 25UCR24SL01
A6: B. COM STRATEGIC FINANCE | B6: UG | C6: Shift 2 | D6: Dr. V. Sagaya Pricilla | E6: Digital Marketing in the AI Era-Part 1 | F6: 25UCF24SL01
A7: BIOCHEMISTRY | B7: PG | C7: Shift 2 | D7: Dr P G GEEGI | E7: Fundamentals of plant pathology | F7: 25PBI2SL02
A8: BIOTECHNOLOGY | B8: PG | C8: Shift 2 | D8: Dr.C.Muthusamy | E8: Bioreactors | F8: 25PBT2SL02
A9: BIOTECHNOLOGY | B9: UG | C9: Shift 2 | D9: Dr Agnes Preethy H | E9: ANIMAL WASTE MANAGEMENT | F9: 25UBT24SL01
A10: BOTANY | B10: UG | C10: Shift 1 | D10: Dr. Johny Kumar Tagore A | E10: ANATOMY OF FLOWERING PLANTS | F10: 25UBO24SL01
A11: BUSINESS ADMINISTRATION | B11: UG | C11: Shift 2 | D11: ANANDA RAJ B | E11: Entrepreneurship Skills and Digital Marketing Strategies | F11: 25UBU24SL01
A12: BUSINESS ADMINISTRATION | B12: UG | C12: Shift 2 | D12: SINDHUJA P | E12: Entrepreneurship Skills and Digital Marketing Strategies | F12: 25UBU24SL01
... A57: VISCOM TECHNOLOGY | B57: UG | C57: Shift 2 | D57: Dr. Jeffrin Aldo J | E57: Communication Skills | F57: 25UVC24SL01

Sheet Sheet2
A1: Department | B1: Programme | C1: Shift | D1: Staff Incharge | E1: Course Title | F1: Course Code | G1: Reg. Nol | H1: Name
A2: ARTIFICIAL INTELLIGENCE | B2: PG | C2: Shift 2 | D2: C.MOHANRAJA | E2: Research Writing | F2: =_xlfn.XLOOKUP(E2, Sheet1!E:E, Sheet1!F:F, "Not Found") -> 25PAI2SL02 | G2: 25PAI801 | H2: SHRI HARISH V M
A3: ARTIFICIAL INTELLIGENCE | B3: PG | C3: Shift 2 | D3: C.MOHANRAJA | E3: Research Writing | F3: =_xlfn.XLOOKUP(E3, Sheet1!E:E, Sheet1!F:F, "Not Found") -> 25PAI2SL02 | G3: 25PAI805 | H3: CHRIS MATTHEW
A4: ARTIFICIAL INTELLIGENCE | B4: PG | C4: Shift 2 | D4: C.MOHANRAJA | E4: Research Writing | F4: =_xlfn.XLOOKUP(E4, Sheet1!E:E, Sheet1!F:F, "Not Found") -> 25PAI2SL02 | G4: 25PAI811 | H4: JAFFIC JESHMA J
A5: ARTIFICIAL INTELLIGENCE | B5: PG | C5: Shift 2 | D5: C.MOHANRAJA | E5: Research Writing | F5: =_xlfn.XLOOKUP(E5, Sheet1!E:E, Sheet1!F:F, "Not Found") -> 25PAI2SL02 | G5: 25PAI812 | H5: MOHAMED RIYAS M
A6: ARTIFICIAL INTELLIGENCE | B6: PG | C6: Shift 2 | D6: C.MOHANRAJA | E6: Research Writing | F6: =_xlfn.XLOOKUP(E6, Sheet1!E:E, Sheet1!F:F, "Not Found") -> 25PAI2SL02 | G6: 25PAI816 | H6: VISWAA G
A7: ARTIFICIAL INTELLIGENCE | B7: PG | C7: Shift 2 | D7: C.MOHANRAJA | E7: Research Writing | F7: =_xlfn.XLOOKUP(E7, Sheet1!E:E, Sheet1!F:F, "Not Found") -> 25PAI2SL02 | G7: 25PAI823 | H7: LINITH MICHAELIN P
A8: ARTIFICIAL INTELLIGENCE | B8: UG | C8: Shift 2 | D8: Dr. S. LAKSHMANAN | E8: Python for Data Science | F8: =_xlfn.XLOOKUP(E8, Sheet1!E:E, Sheet1!F:F, "Not Found") -> 25UAI24SL01 | G8: 25UAI511 | H8: ARIYA KANNAA RA
A9: ARTIFICIAL INTELLIGENCE | B9: UG | C9: Shift 2 | D9: Dr. S. LAKSHMANAN | E9: Python for Data Science | F9: =_xlfn.XLOOKUP(E9, Sheet1!E:E, Sheet1!F:F, "Not Found") -> 25UAI24SL01 | G9: 25UAI517 | H9: KODEESWAR M
A10: ARTIFICIAL INTELLIGENCE | B10: UG | C10: Shift 2 | D10: Dr. S. LAKSHMANAN | E10: Python for Data Science | F10: =_xlfn.XLOOKUP(E10, Sheet1!E:E, Sheet1!F:F, "Not Found") -> 25UAI24SL01 | G10: 25UAI524 | H10: DINESH S
A11: ARTIFICIAL INTELLIGENCE | B11: UG | C11: Shift 2 | D11: Dr. S. LAKSHMANAN | E11: Python for Data Science | F11: =_xlfn.XLOOKUP(E11, Sheet1!E:E, Sheet1!F:F, "Not Found") -> 25UAI24SL01 | G11: 25UAI526 | H11: ALWIN L
A12: ARTIFICIAL INTELLIGENCE | B12: UG | C12: Shift 2 | D12: Dr. S. LAKSHMANAN | E12: Python for Data Science | F12: =_xlfn.XLOOKUP(E12, Sheet1!E:E, Sheet1!F:F, "Not Found") -> 25UAI24SL01 | G12: 25UAI527 | H12: KRITHIK ROSHAN Y
A13: ARTIFICIAL INTELLIGENCE | B13: UG | C13: Shift 2 | D13: Dr. S. LAKSHMANAN | E13: Python for Data Science | F13: =_xlfn.XLOOKUP(E13, Sheet1!E:E, Sheet1!F:F, "Not Found") -> 25UAI24SL01 | G13: 25UAI529 | H13: SUBRAJA M
... A327: CHEMISTRY | B327: PG | C327: Shift 2 | D327: Dr.P.Arockia Doss | E327: Nano Materials-synthesis properties and applications | F327: =_xlfn.XLOOKUP(E327, Sheet1!E:E, Sheet1!F:F, "Not Found") -> 25PCH2SL02 | G327: 25PCH828 | H327: Kiruthika S
A328: COMMERCE | B328: UG | C328: Shift 1 | D328: Dr. M.ANTONY JESURAJA | E328: Forms of Business Organisation | F328: 25UCO24SL01 | G328: 25UCO105 | H328: CASPAR RUBHAN R
A329: COMMERCE | B329: UG | C329: Shift 1 | D329: Dr. M.ANTONY JESURAJA | E329: Forms of Business Organisation | F329: 25UCO24SL01 | G329: 25UCO112 | H329: PREJEWAL KEVIN S
A330: COMMERCE | B330: UG | C330: Shift 1 | D330: Dr. M.ANTONY JESURAJA | E330: Forms of Business Organisation | F330: 25UCO24SL01 | G330: 25UCO119 | H330: AMAL DAITARS A
A331: COMMERCE | B331: UG | C331: Shift 1 | D331: Dr. M.ANTONY JESURAJA | E331: Forms of Business Organisation | F331: 25UCO24SL01 | G331: 25UCO137 | H331: JEEVAN BHARATH J
A332: COMMERCE | B332: UG | C332: Shift 1 | D332: Dr. M.ANTONY JESURAJA | E332: Forms of Business Organisation | F332: 25UCO24SL01 | G332: 25UCO147 | H332: SUDHARSAN S
A333: COMMERCE | B333: UG | C333: Shift 1 | D333: Dr. M.ANTONY JESURAJA | E333: Forms of Business Organisation | F333: 25UCO24SL01 | G333: 25UCO148 | H333: CALEB XAVIER J A
A334: COMMERCE | B334: UG | C334: Shift 1 | D334: Dr. M.ANTONY JESURAJA | E334: Forms of Business Organisation | F334: 25UCO24SL01 | G334: 25UCO152 | H334: BENNY JADEN J
A335: COMMERCE | B335: UG | C335: Shift 1 | D335: Dr. M.ANTONY JESURAJA | E335: Forms of Business Organisation | F335: 25UCO24SL01 | G335: 25UCO158 | H335: SOORYA PRAKASH M G
A336: COMMERCE | B336: UG | C336: Shift 1 | D336: Dr. M.ANTONY JESURAJA | E336: Forms of Business Organisation | F336: 25UCO24SL01 | G336: 25UCO164 | H336: INBATHAMILAN A
A337: COMMERCE | B337: UG | C337: Shift 1 | D337: Dr. M.ANTONY JESURAJA | E337: Forms of Business Organisation | F337: 25UCO24SL01 | G337: 25UCO165 | H337: SHAN LANSTAN
A338: COMMERCE | B338: UG | C338: Shift 1 | D338: Dr. M.ANTONY JESURAJA | E338: Forms of Business Organisation | F338: 25UCO24SL01 | G338: 25UCO170 | H338: SAI GANESH M
A339: COMMERCE | B339: UG | C339: Shift 1 | D339: Dr. M.ANTONY JESURAJA | E339: Forms of Business Organisation | F339: 25UCO24SL01 | G339: 25UCO205 | H339: YOKESH RAJ J
... A348: COMMERCE | B348: UG | C348: Shift 1 | D348: Dr. M.ANTONY JESURAJA | E348: Forms of Business Organisation | F348: 25UCO24SL01 | G348: 25UCO255 | H348: KIRUTHICK S
A349: COMMERCE | B349: PG | C349: Shift 1 | D349: Dr. M.ANTONY JESURAJA | E349: Introduction to Banking and Financial Markets | F349: =_xlfn.XLOOKUP(E349, Sheet1!E:E, Sheet1!F:F, "Not Found") -> 25PCO2SL02 | G349: 25PCO127 | H349: DEEPAK KARTHIKEYAN A
A350: COMMERCE | B350: PG | C350: Shift 1 | D350: Dr. M.ANTONY JESURAJA | E350: Introduction to Banking and Financial Markets | F350: =_xlfn.XLOOKUP(E350, Sheet1!E:E, Sheet1!F:F, "Not Found") -> 25PCO2SL02 | G350: 25PCO136 | H350: KOUSHIK S
A351: COMMERCE | B351: UG | C351: Shift 2 | D351: Dr.Berkmans J | E351: Forms of Business Organisation | F351: 25UCO24SL01 | G351: 25UCO501 | H351: ALBERT A
A352: COMMERCE | B352: UG | C352: Shift 2 | D352: Dr.Berkmans J | E352: Forms of Business Organisation | F352: 25UCO24SL01 | G352: 25UCO507 | H352: SRINIVASAN N
A353: COMMERCE | B353: UG | C353: Shift 2 | D353: Dr.Berkmans J | E353: Forms of Business Organisation | F353: 25UCO24SL01 | G353: 25UCO508 | H353: SATHIYA MUTHU M
A354: COMMERCE | B354: UG | C354: Shift 2 | D354: Dr.Berkmans J | E354: Forms of Business Organisation | F354: 25UCO24SL01 | G354: 25UCO510 | H354: RAHUL SRINIVASAN S
A355: COMMERCE | B355: UG | C355: Shift 2 | D355: Dr.Berkmans J | E355: Forms of Business Organisation | F355: 25UCO24SL01 | G355: 25UCO512 | H355: VINCENT RAJ B
A356: COMMERCE | B356: UG | C356: Shift 2 | D356: Dr.Berkmans J | E356: Forms of Business Organisation | F356: 25UCO24SL01 | G356: 25UCO513 | H356: VIBINBHARATHI K
A357: COMMERCE | B357: UG | C357: Shift 2 | D357: Dr.Berkmans J | E357: Forms of Business Organisation | F357: 25UCO24SL01 | G357: 25UCO514 | H357: NAVEEN V N
A358: COMMERCE | B358: UG | C358: Shift 2 | D358: Dr.Berkmans J | E358: Forms of Business Organisation | F358: 25UCO24SL01 | G358: 25UCO516 | H358: DARUNKUMAR R
A359: COMMERCE | B359: UG | C359: Shift 2 | D359: Dr.Berkmans J | E359: Forms of Business Organisation | F359: 25UCO24SL01 | G359: 25UCO519 | H359: MOHAMED ASIF RAHMAN A
A360: COMMERCE | B360: UG | C360: Shift 2 | D360: Dr.Berkmans J | E360: Forms of Business Organisation | F360: 25UCO24SL01 | G360: 25UCO522 | H360: DHARMAN B
A361: COMMERCE | B361: UG | C361: Shift 2 | D361: Dr.Berkmans J | E361: Forms of Business Organisation | F361: 25UCO24SL01 | G361: 25UCO524 | H361: AUGUSTIN INFANT J
...
